Workbook

Sheet Settings
A1: CLOUDIT AUTOMATION & ACCOUNTING SERVICES LLC
A2: System Settings — Change yellow cells to update all calculations
A4: GENERAL SETTINGS
A5: Parameter | B5: Value | C5: Unit | D5: Notes
A6: Standard Working Hours/Month | B6: 160 | C6: Hours | D6: 22 days × 8 hrs
A7: Working Days/Month | B7: 20 | C7: Days
A8: INR to USD Conversion Rate | B8: 85 | C8: INR/USD | D8: Change this when rate changes
A9: Period | B9: Jan 2026 | D9: Update each month
A11: UTILIZATION THRESHOLDS
A12: Parameter | B12: Value | C12: Unit | D12: Notes
A13: High Utilization (Green) | B13: 0.85 | C13: % | D13: Above this = overloaded/optimal
A14: Medium Utilization (Yellow) | B14: 0.65 | C14: % | D14: Between this and High = review
A15: Low Utilization (Red) | B15: 0.5 | C15: % | D15: Below this = underutilized
A17: INCREMENT SCORING WEIGHTS
A18: Dimension | B18: Weight | C18: Max Score | D18: Notes
A19: Utilization Score | B19: 0.25 | C19: 25 | D19: Billable hours / standard hours
A20: Client Profitability | B20: 0.2 | C20: 20 | D20: Revenue vs cost of clients served
A21: Efficiency Score | B21: 0.15 | C21: 15 | D21: Work Composer accuracy
A22: Tenure & Loyalty | B22: 0.15 | C22: 15 | D22: Years of service
A23: Designation & Responsibility | B23: 0.15 | C23: 15 | D23: Role complexity
A24: Revenue per Head | B24: 0.1 | C24: 10 | D24: Billing / employee cost
A25: Total | B25: =SUM(B19:B24) -> 1 | C25: =SUM(C19:C24) -> 100 | D25: Must equal 100% / 100
A27: INCREMENT SLAB PERCENTAGES (v2)
A28: Slab | B28: Increment % | C28: Score Range
A29: Scoring Model | B29: Historical 60% + Future 40%
A31: Exceptional | B31: 0.175 | C31: Score 85-100 → 17.5%
A32: High Performer | B32: 0.12 | C32: Score 70-84 → 12%
A33: Meets Expectations | B33: 0.075 | C33: Score 50-69 → 7.5%
A34: Below Expectations | B34: 0.03 | C34: Score 30-49 → 3%
A35: Underperformer | B35: 0 | C35: Score 0-29 → 0%

Sheet ① Timelog Input
A1: PASTE YOUR TIMELOG DATA HERE
A2: Instructions: Copy-paste from your timelog export. Keep headers in Row 3. Max 200 employees.
A3: ID | B3: Employee Name | C3: Employee ID | D3: Reporting Manager | E3: Controller | F3: Employment Type | G3: Designation | H3: Department | I3: Total Hours | J3: Billable Hours | K3: Approved Hours | L3: Efficiency Score | M3: Work Composer Time | N3: WC Diff Hours | O3: WC Percentage | P3: Last Updated | Q3: 406 CONSULTING LLC | R3: 4P TAXES LLC | S3: AB CAPSTONE GROUP | T3: ABACUS BUSINESS SOLUTIONS, LLC | U3: ACE CPA | V3: ACT NOW FINANCIAL SERVICES, LLC | W3: ACTION ACCOUNTING | X3: AMI US HOLDING INC. | Y3: ANCIENT CITY ACCOUNTING LLC | Z3: BEAM ACCOUNTING INC | AA3: BORISTAX INC | AB3: BRADLEY FINANCIAL SERVICES LLC | AC3: BRIGHTSKIES BUSINESS SERVICES, LLC | AD3: BUSINESS NAVIGATORS LLC | AE3: CASCFO Advisory- United States | AF3: CENTURION TAX AND ACCOUNTING | AG3: CHRIS WHALEN CPA, LLC | AH3: CLARK FINANCIALS | AI3: CLOUDIT | AJ3: COHEN AND ASSOCIATES | AK3: DOR BUSINESS GROUP LLC | AL3: EVERMORE FINANCIAL SERVICES LLC | AM3: Fleming Accounting Solutions | AN3: FULL COMPLIANCE, LLC | AO3: H J EDWARDS | AP3: HELLO ACCOUNTAX | AQ3: HIA TAX | AR3: IAM ACCOUNTING LLC | AS3: INNOVATIVE CONSULTING & SOLUTIONS, LLC | AT3: INVENT WEALTH, CPA | AU3: jmWILLIAMS, CPA, LLP | AV3: JOHNSON & ROBINSON LLC | AW3: LEANCORP ACCOUNTING | AX3: LIFETIME FUNDING, LLC | AY3: MAINSPRING SOLUTIONS | AZ3: MARTIN D. EISENSTEIN, CPA | BA3: MATHESON & ASSOCIATES | BB3: MCFADDEN ACCOUNTING | BC3: MEJIA & ASSOCIATES, INC. | BD3: MERAKI ACCOUNTING & TAX LLC | BE3: NATIONAL TAX CENTERS, LLC | BF3: NEW AGE IRON WORKS, INC. | BG3: NEWELL TAYLOR CPA | BH3: NUMBER NUTTZ CONSULTING | BI3: ONE KOSMOS, INC. | BJ3: PORCHEA & LOTT ACCOUNTING | BK3: PROVISION ACCOUNTING SOLUTIONS | BL3: PW ADVISORS LLC | BM3: RATHEL’S ACCOUNTING SERVICE, INC | BN3: ROSEN KUSLANSKY CPA PC | BO3: RRAW CPA LLP | BP3: RTW XXACT ENTERPRISES, LLC | BQ3: SFSG BILLING PROJECT | BR3: SMALLHOLD INC | BS3: SOUTH FLORIDA SECURITY GROUP | BT3: TAX GEEK LLC | BU3: THE PROFIT SCALE THRIVE | BV3: THE TAX CUTTERY | BW3: THINKING MAPS, INC. | BX3: TREE OF LIFE FUNDING INC | BY3: TRI SCAPES | BZ3: WB MORROW | CA3: WE ARE QUADRANT | CB3: WIGGS CPA TAX & ACCOUNTING | CC3: XPERT BOOKKEEPING LLC | CD3: Total Firms Hours
A4: 1 | B4: Ankit | C4: CAS-IH_1070 | D4: Jasleen.D | E4: Jasleen.D | F4: In-house | G4: Associate | H4: Accounting | I4: 113.42 | J4: 113.42 | K4: 113.42 | L4: 100% | M4: 111.38333 | N4: 2.0366667 | O4: 1.83% | P4: 03/03/2026 | R4: 21.5 | AI4: 5.84 | AR4: 86.08 | CD4: 113.42
A5: 2 | B5: Astha.D | C5: CAS-IH_1092 | D5: Anshul Ohri | E5: Jasleen.D | F5: In-house | G5: Associate | H5: Accounting | I5: 156.75 | J5: 156.75 | K5: 156.75 | L5: 100% | M5: 152.16667 | N5: 4.5833333 | O5: 3.01% | P5: 03/03/2026 | AT5: 156.75 | CD5: 156.75
A6: 3 | B6: Pragati.S | C6: CAS-IH_1105 | D6: Anshul Ohri | E6: Jasleen.D | F6: In-house | G6: Asst. Team Lead | H6: Accounting | I6: 125.58 | J6: 125.58 | K6: 125.58 | L6: 100% | O6: -- | P6: 03/03/2026 | AC6: 69.58 | AI6: 16.61 | AT6: 3.82 | AY6: 27.4 | BA6: 8.17 | CD6: 125.58
A7: 4 | B7: Anshul.O | C7: CAS-IH_1109 | D7: Jasleen.D | E7: Jasleen.D | F7: In-house | G7: Team Lead | H7: Accounting | I7: 157.42 | J7: 157.42 | K7: 157.42 | L7: 100% | M7: 130.46667 | N7: 26.953333 | O7: 20.66% | P7: 03/03/2026 | Y7: 4.5 | AC7: 31.67 | AD7: 9.5 | AI7: 19.5 | AQ7: 6 | AT7: 19.5 | AY7: 6 | BA7: 0.5 | BG7: 2 | BO7: 5 | BZ7: 53.25 | CD7: 157.42
A8: 5 | B8: Shefali.B | C8: CAS-IH_1122 | D8: Anshul Ohri | E8: Jasleen.D | F8: In-house | G8: Associate | H8: Accounting | I8: 147.41 | J8: 147.41 | K8: 147.41 | L8: 100% | O8: -- | P8: 03/03/2026 | AI8: 5.92 | BA8: 141.49 | CD8: 147.41
A9: 6 | B9: Sandesh.H | C9: CAS-IH_1149 | D9: Anshul Ohri | E9: Jasleen.D | F9: In-house | G9: Associate | H9: Accounting | I9: 166 | J9: 166 | K9: 166 | L9: 100% | O9: -- | P9: 03/03/2026 | AB9: 43.5 | AC9: 122.5 | CD9: 166
A10: 7 | B10: Robin.S | C10: CAS-IH_1162 | D10: Anshul Ohri | E10: Jasleen.D | F10: Remote | G10: Associate | H10: Accounting | I10: 141.24 | J10: 141.24 | K10: 141.24 | L10: 100% | O10: -- | P10: 03/02/2026 | AI10: 1 | AT10: 140.24 | CD10: 141.24
A11: 8 | B11: Vijet.B | C11: CAS-RR_2371 | D11: Anshul Ohri | E11: Jasleen.D | F11: Remote | G11: Associate | H11: Accounting | I11: 157.75 | J11: 157.75 | K11: 157.75 | L11: 100% | O11: -- | P11: 03/03/2026 | AI11: 2 | AQ11: 73 | BG11: 82.75 | CD11: 157.75
A12: 9 | B12: Somya.B | C12: CAS-IH_1169 | D12: Anshul Ohri | E12: Jasleen.D | F12: Retainer | G12: Sr. Associate | H12: Accounting | I12: 146.75 | J12: 146.75 | K12: 146.75 | L12: 100% | O12: -- | P12: 03/03/2026 | Y12: 139.75 | AI12: 7 | CD12: 146.75
A13: 10 | B13: Jasleen.D | C13: CAS-IH_1069 | D13: Andrew Jindal | E13: -- | F13: In-house | G13: Controller | H13: Accounting | I13: 107 | J13: 107 | K13: 107 | L13: 100% | O13: -- | P13: 03/03/2026 | R13: 2 | T13: 6 | Y13: 2 | AB13: 2 | AC13: 2 | AD13: 2 | AE13: 20 | AI13: 54 | AL13: 2 | AQ13: 2 | AR13: 2 | AT13: 2 | AY13: 3 | BA13: 2 | BG13: 2 | BO13: 2 | CD13: 107
A14: 11 | B14: Jyoti | C14: CAS-IH_1037 | D14: Andrew Jindal | E14: -- | F14: In-house | G14: Controller | H14: Accounting, Business Tax, VA | I14: 151.9 | J14: 151.9 | K14: 151.9 | L14: 100% | O14: -- | P14: 03/03/2026 | Q14: 3.75 | AI14: 40.16 | AM14: 0.5 | AN14: 2 | AT14: 89.16 | AZ14: 9.75 | BE14: 3.33 | BK14: 0.75 | BL14: 2.5 | CD14: 151.9
A15: 12 | B15: Vini | C15: CAS-IH_1018 | D15: Andrew Jindal | E15: -- | F15: In-house | G15: Controller | H15: HR | I15: 10.42 | J15: 10.42 | K15: 10.42 | L15: 100% | O15: -- | P15: 03/03/2026 | AI15: 10.42 | CD15: 10.42
A16: 13 | B16: Asmita | C16: CAS-IH_1049 | D16: Jyoti | E16: Jyoti | F16: In-house | G16: Sr. Associate | H16: Accounting, Business Tax | I16: 115.67 | J16: 115.67 | K16: 115.67 | L16: 100% | M16: 132.81667 | N16: -17.146667 | O16: 12.91% | P16: 03/02/2026 | AI16: 1 | AM16: 14.5 | AT16: 18.92 | AU16: 22.75 | AZ16: 23.5 | BE16: 4.75 | BK16: 11.75 | BL16: 7.5 | BT16: 11 | CD16: 115.67
A17: 14 | B17: Nikita | C17: CAS-IH_1041 | D17: Andrew Jindal | E17: -- | F17: In-house | G17: Controller | H17: Accounting, Business Tax, VA, L&D | I17: 101 | J17: 101 | K17: 101 | L17: 100% | O17: -- | P17: 02/26/2026 | U17: 4 | AI17: 72 | BM17: 9 | CA17: 14 | CB17: 2 | CD17: 101
A18: 15 | B18: Ayushi | C18: CAS-IH_1051 | D18: Andrew Jindal | E18: -- | F18: In-house | G18: Asst. Controller | H18: Accounting, Business Tax | L18: -- | O18: --
A19: 16 | B19: Shefali | C19: CAS-IH_1065 | D19: Nikita Shah | E19: Nikita Shah | F19: In-house | G19: Team Lead | H19: Accounting | I19: 144.35 | J19: 144.35 | K19: 144.35 | L19: 100% | O19: -- | P19: 03/03/2026 | U19: 29.5 | W19: 2 | AI19: 16.59 | BB19: 2 | BL19: 33.84 | BM19: 2 | BV19: 0.5 | BW19: 6.92 | CA19: 49 | CC19: 2 | CD19: 144.35
A20: 17 | B20: Rashi | C20: CAS-IH_1077 | D20: Vinita Dagar | E20: Vinita Dagar | F20: In-house | G20: Asst. Manager | H20: HR | L20: -- | O20: --
A21: 18 | B21: Gaganjot | C21: CAS-IH_1159 | D21: Shefali | E21: Nikita Shah | F21: In-house | G21: Asst. Team Lead | H21: Accounting, Business Tax | L21: -- | O21: --
A22: 19 | B22: Robin | C22: CAS-IH_1005 | D22: Jyoti | E22: Jyoti | F22: In-house | G22: Sr. Associate | H22: Accounting | I22: 165.25 | J22: 162.25 | K22: 162.25 | L22: 98.18% | O22: -- | P22: 03/03/2026 | AI22: 1.5 | AN22: 130.25 | AZ22: 5 | BC22: 1 | BK22: 6 | BS22: 18.5 | CD22: 162.25
A23: 20 | B23: Nishu | C23: CAS-IH_1038 | D23: Robin | E23: Jyoti | F23: In-house | G23: Associate | H23: Accounting, Business Tax, VA | I23: 132.67 | J23: 132.67 | K23: 132.67 | L23: 100% | O23: -- | P23: 03/03/2026 | AN23: 132.67 | CD23: 132.67
A24: 21 | B24: Pinky | C24: CAS-RT_2045 | D24: Nikita Shah | E24: Nikita Shah | F24: Remote | G24: Manager | H24: Accounting | I24: 64.27 | J24: 64.27 | K24: 64.27 | L24: 100% | O24: -- | P24: 03/03/2026 | S24: 64.27 | CD24: 64.27
A25: 22 | B25: Preety | C25: CAS-IH_1056 | D25: Nikita Shah | E25: Nikita Shah | F25: In-house | G25: Team Lead | H25: Accounting, Business Tax | I25: 81 | J25: 81 | K25: 81 | L25: 100% | O25: -- | P25: 03/03/2026 | V25: 2.75 | AG25: 10 | AI25: 15.5 | AV25: 4.5 | AW25: 1 | BL25: 39.75 | BN25: 3 | CB25: 4.5 | CD25: 81
A26: 23 | B26: Urvashi | C26: CAS-RT_2063 | D26: Pinky | E26: Nikita Shah | F26: Remote | G26: Associate | H26: Accounting | I26: 104.09 | J26: 104.09 | K26: 104.09 | L26: 100% | O26: -- | P26: 03/03/2026 | S26: 104.09 | CD26: 104.09
A27: 24 | B27: Melita | C27: CAS-IH_1046 | D27: Smriti Shah | E27: Smriti Shah | F27: In-house | G27: Team Lead | H27: Individual Tax | I27: 178.09 | J27: 178.09 | K27: 178.09 | L27: 100% | O27: -- | P27: 03/03/2026 | AI27: 98.5 | AM27: 4.34 | AN27: 31.75 | AT27: 6 | AU27: 35.41 | AZ27: 1.75 | BC27: 0.17 | BK27: 0.17 | CD27: 178.09
A28: 25 | B28: Bhawna | C28: CAS-RR_2077 | D28: Jyoti | E28: Jyoti | F28: Retainer | G28: Manager | H28: Accounting | I28: 189.58 | J28: 189.58 | K28: 189.58 | L28: 100% | N28: 189.58 | O28: -- | P28: 03/02/2026 | BR28: 68.01 | BY28: 121.57 | CD28: 189.58
A29: 26 | B29: Anand | C29: CAS-RT_2078 | D29: Nikita Shah | E29: Nikita Shah | F29: Remote | G29: Associate | H29: Accounting | I29: 159.38 | J29: 159.38 | K29: 159.38 | L29: 100% | M29: 158.06667 | N29: 1.3133333 | O29: 0.83% | P29: 03/03/2026 | AX29: 88.78 | BX29: 70.6 | CD29: 159.38
A30: 27 | B30: Shivani | C30: CAS-RT_2102 | D30: Preety | E30: Nikita Shah | F30: Remote | G30: Associate | H30: Accounting | I30: 55.11 | J30: 55.11 | K30: 55.11 | L30: 100% | O30: -- | P30: 02/27/2026 | AG30: 49.1 | BN30: 6.01 | CD30: 55.11
A31: 28 | B31: Sreeja | C31: CAS-RT_2108 | D31: Pinky | E31: Nikita Shah | F31: Remote | G31: Manager | H31: Accounting | I31: 90.58 | J31: 90.58 | K31: 90.58 | L31: 100% | O31: -- | P31: 03/03/2026 | S31: 90.58 | CD31: 90.58
A32: 29 | B32: Divya.M | C32: CAS-RT_2113 | D32: Preety | E32: Nikita Shah | F32: Remote | G32: Manager | H32: Accounting | I32: 82.67 | J32: 82.67 | K32: 82.67 | L32: 100% | M32: 83.25 | N32: -0.58 | O32: 0.7% | P32: 02/25/2026 | V32: 23.25 | AG32: 44.42 | AZ32: 5 | BN32: 10 | CD32: 82.67
A33: 30 | B33: Kritika | C33: CAS-IH_1102 | D33: Sachi Mazumdar | E33: Sachi Mazumdar | F33: In-house | G33: Manager | H33: FP&A | I33: 163 | J33: 139 | K33: 139 | L33: 85.28% | O33: -- | P33: 03/03/2026 | X33: 139 | CD33: 139
A34: 31 | B34: Abhilash | C34: CAS-IH_1061 | D34: Smriti Shah | E34: Smriti Shah | F34: In-house | G34: Sr. Associate | H34: Individual Tax | I34: 99.34 | J34: 99.34 | K34: 99.34 | L34: 100% | M34: 186.15 | N34: -86.81 | O34: 46.63% | P34: 03/03/2026 | Q34: 2.5 | AG34: 54.84 | AI34: 37.5 | AM34: 1.5 | BL34: 3 | CD34: 99.34
A35: 32 | B35: Kavita | C35: CAS-IH_1108 | D35: Sachi Mazumdar | E35: Sachi Mazumdar | F35: In-house | G35: Manager | H35: FP&A | I35: 132 | J35: 132 | K35: 132 | L35: 100% | O35: -- | P35: 02/25/2026 | X35: 132 | CD35: 132
A36: 33 | B36: Sakshi | C36: CAS-IH_1078 | D36: Nikita Shah | E36: Nikita Shah | F36: In-house | G36: Associate | H36: Accounting | I36: 114.48 | J36: 114.48 | K36: 114.48 | L36: 100% | O36: -- | P36: 03/03/2026 | AI36: 2.08 | BQ36: 112.4 | CD36: 114.48
A37: 34 | B37: Suhani | C37: CAS-RR_2370 | D37: Ayushi | E37: Ayushi | F37: Retainer | G37: Team Lead | H37: Accounting | I37: 136.75 | J37: 136.75 | K37: 136.75 | L37: 100% | O37: -- | P37: 03/03/2026 | AA37: 25.5 | AI37: 32.5 | AK37: 3 | AP37: 6.75 | BD37: 6 | BF37: 5 | BK37: 8 | BP37: 10 | BT37: 10 | CA37: 30 | CD37: 136.75
A38: 35 | B38: Shradha | C38: CAS-IH_1082 | D38: Jyoti | E38: Jyoti | F38: In-house | G38: Sr. Associate | H38: Accounting | I38: 158.67 | J38: 154.17 | K38: 154.17 | L38: 97.16% | O38: -- | P38: 03/03/2026 | AI38: 3 | AN38: 144.17 | BS38: 7 | CD38: 154.17
A39: 36 | B39: Ridhi.G | C39: CAS-IH_1146 | D39: Shefali | E39: Nikita Shah | F39: In-house | G39: Asst. Team Lead | H39: Accounting, Business Tax | I39: 115.74 | J39: 115.74 | K39: 115.74 | L39: 100% | O39: -- | P39: 03/03/2026 | U39: 33.16 | AI39: 3.5 | BB39: 16.42 | BL39: 20.74 | CA39: 41.92 | CD39: 115.74
A40: 37 | B40: Bhairavi.M | C40: CAS-IH_1160 | D40: Suhani | E40: Ayushi | F40: In-house | G40: Associate | H40: Accounting | I40: 165 | J40: 149 | K40: 149 | L40: 90.3% | M40: 165.43333 | N40: -16.433333 | O40: 9.93% | P40: 03/03/2026 | AA40: 135.75 | BF40: 13.25 | CD40: 149
...

Sheet ② Salary Input
A1: PASTE YOUR SALARY REGISTER HERE
A2: Instructions: Copy-paste monthly salary register. Keep headers in Row 3. Employee Number must match Timelog Employee ID.
A3: Employee Number | B3: Employee Name | C3: Employee Type | D3: Basic | E3: Basic Pay | F3: House Rent Allowance | G3: Conveyance Allowance | H3: Variable Incentive | I3: Fixed Allowance | J3: Hourly Professional Fees | K3: Variable Pay | L3: Bonus | M3: Reimbursement | N3: Gross Pay | O3: Income Tax | P3: Tax on Income | Q3: Surcharge | R3: Cess | S3: Total Income Tax | T3: Withheld Salary | U3: Business Expense Reimbursements | V3: Net Pay
A4: CAS-IH_1005 | B4: Rajesh Gujrati | C4: employee | D4: 35000 | E4: 0 | F4: 17500 | G4: 5000 | H4: 12500 | I4: 0 | J4: 0 | K4: 0 | L4: 0 | M4: 0 | N4: 70000 | O4: 0 | P4: 0 | Q4: 0 | R4: 0 | S4: 0 | T4: 0 | U4: 0 | V4: 70000
A5: CAS-IH_1038 | B5: Nishu Sharma | C5: employee | D5: 21500 | E5: 0 | F5: 10750 | G5: 4750 | H5: 6000 | I5: 0 | J5: 0 | K5: 0 | L5: 0 | M5: 0 | N5: 43000 | O5: 0 | P5: 0 | Q5: 0 | R5: 0 | S5: 0 | T5: 0 | U5: 0 | V5: 43000
A6: CAS-IH_1046 | B6: Melita Dias | C6: employee | D6: 67500 | E6: 0 | F6: 33750 | G6: 16875 | H6: 0 | I6: 16875 | J6: 0 | K6: 0 | L6: 0 | M6: 0 | N6: 135000 | O6: 0 | P6: 9615 | Q6: 0 | R6: 385 | S6: 10000 | T6: 0 | U6: 0 | V6: 125000
A7: CAS-IH_1049 | B7: Asmita Mandan | C7: employee | D7: 31250 | E7: 0 | F7: 15625 | G7: 7813 | H7: 3000 | I7: 4812 | J7: 0 | K7: 0 | L7: 0 | M7: 0 | N7: 62500 | O7: 0 | P7: 0 | Q7: 0 | R7: 0 | S7: 0 | T7: 0 | U7: 0 | V7: 62500
A8: CAS-IH_1056 | B8: Preety Soni | C8: employee | D8: 50000 | E8: 0 | F8: 25000 | G8: 12500 | H8: 0 | I8: 12500 | J8: 0 | K8: 0 | L8: 0 | M8: 0 | N8: 100000 | O8: 0 | P8: 0 | Q8: 0 | R8: 0 | S8: 0 | T8: 0 | U8: 0 | V8: 100000
A9: CAS-IH_1061 | B9: Jillela Abhilash | C9: employee | D9: 50000 | E9: 0 | F9: 25000 | G9: 12500 | H9: 0 | I9: 12500 | J9: 0 | K9: 0 | L9: 0 | M9: 0 | N9: 100000 | O9: 0 | P9: 0 | Q9: 0 | R9: 0 | S9: 0 | T9: 0 | U9: 0 | V9: 100000
A10: CAS-IH_1065 | B10: Shefali Mantri | C10: employee | D10: 67500 | E10: 0 | F10: 33750 | G10: 13750 | H10: 20000 | I10: 0 | J10: 0 | K10: 0 | L10: 0 | M10: 0 | N10: 135000 | O10: 0 | P10: 9615 | Q10: 0 | R10: 385 | S10: 10000 | T10: 0 | U10: 0 | V10: 125000
A11: CAS-IH_1070 | B11: Ankit Gupta | C11: employee | D11: 30000 | E11: 0 | F11: 15000 | G11: 7500 | H11: 0 | I11: 7500 | J11: 0 | K11: 0 | L11: 0 | M11: 0 | N11: 60000 | O11: 0 | P11: 0 | Q11: 0 | R11: 0 | S11: 0 | T11: 0 | U11: 0 | V11: 60000
A12: CAS-IH_1077 | B12: Rashi Varshney | C12: employee | D12: 35000 | E12: 0 | F12: 17500 | G12: 8750 | H12: 0 | I12: 8750 | J12: 0 | K12: 0 | L12: 0 | M12: 0 | N12: 70000 | O12: 0 | P12: 0 | Q12: 0 | R12: 0 | S12: 0 | T12: 0 | U12: 0 | V12: 70000
A13: CAS-IH_1078 | B13: Sakshi Bansal | C13: employee | D13: 27500 | E13: 0 | F13: 13750 | G13: 6875 | H13: 0 | I13: 6875 | J13: 0 | K13: 0 | L13: 0 | M13: 0 | N13: 55000 | O13: 0 | P13: 0 | Q13: 0 | R13: 0 | S13: 0 | T13: 0 | U13: 0 | V13: 55000
A14: CAS-IH_1082 | B14: Shradha Jain | C14: employee | D14: 25500 | E14: 0 | F14: 12750 | G14: 6375 | H14: 0 | I14: 6375 | J14: 0 | K14: 0 | L14: 0 | M14: 0 | N14: 51000 | O14: 0 | P14: 0 | Q14: 0 | R14: 0 | S14: 0 | T14: 0 | U14: 0 | V14: 51000
A15: CAS-IH_1092 | B15: Astha Dhanotiya | C15: employee | D15: 22500 | E15: 0 | F15: 11250 | G15: 5625 | H15: 5000 | I15: 625 | J15: 0 | K15: 0 | L15: 0 | M15: 0 | N15: 45000 | O15: 0 | P15: 0 | Q15: 0 | R15: 0 | S15: 0 | T15: 0 | U15: 0 | V15: 45000
... A121: CAS-RT_2319 | B121: Shikha Agrawal | C121: contractor | D121: 0 | E121: 500 | F121: 0 | G121: 0 | H121: 0 | I121: 0 | J121: 38700 | K121: 0 | L121: 0 | M121: 0 | N121: 39200 | O121: 3920 | P121: 0 | Q121: 0 | R121: 0 | S121: 0 | T121: 0 | U121: 0 | V121: 35280

Sheet ③ Billing Input
A1: ENTER CLIENT BILLING HERE
A2: Instructions: Enter billing in USD. INR auto-calculates using conversion rate from Settings. Max 100 clients. | I2: Project code from Worksheet
A3: S.No | B3: Client Name | C3: Controller | D3: Service(s) | E3: Billing USD (Monthly) | F3: Billing INR (Auto) | G3: Conversion Rate → | H3: =Settings!B8 -> 85 | I3: Project Code | J3: Contract Hrs | K3: # End Clients | L3: Firm Status
A4: 1 | B4: FULL COMPLIANCE, LLC | C4: Ammie, Jyoti | D4: Acctg, B.Tax, I.Tax, VA | E4: 2600 | F4: =IF(E4="",0,E4*Settings!B8) -> 221000 | I4: CAS 102 | J4: 640 | K4: 89 | L4: In Progress
A5: 2 | B5: MEJIA & ASSOCIATES, INC. | C5: Jyoti | D5: Accounting | E5: 1800 | F5: =IF(E5="",0,E5*Settings!B8) -> 153000 | I5: CAS 103 | J5: 161 | L5: Active
A6: 3 | B6: SOUTH FLORIDA SECURITY GROUP | C6: Jyoti | D6: Accounting | E6: 2320 | F6: =IF(E6="",0,E6*Settings!B8) -> 197200 | I6: CAS 115 | J6: 320 | L6: Active
A7: 4 | B7: SOUTH FLORIDA SECURITY GROUP- Billing | C7: Jyoti | D7: Accounting | E7: 1500 | F7: =IF(E7="",0,E7*Settings!B8) -> 127500 | I7: CAS 115 | J7: 320 | L7: Active
A8: 5 | B8: BEAM ACCOUNTING INC | C8: Nikita | D8: Accounting | E8: 650 | F8: =IF(E8="",0,E8*Settings!B8) -> 55250 | I8: CAS 118 | J8: 40 | K8: 13 | L8: In Progress
A9: 6 | B9: BRIGHTSKIES BUSINESS SERVICES, LLC | C9: Jasleen.D | D9: Accounting | E9: 2600 | F9: =IF(E9="",0,E9*Settings!B8) -> 221000 | I9: CAS 123 | J9: 400 | K9: 41 | L9: In Progress
A10: 7 | B10: AB CAPSTONE | C10: Nikita | D10: Accounting | E10: 1800 | F10: =IF(E10="",0,E10*Settings!B8) -> 153000 | I10: CAS 134 | J10: 240 | K10: 27 | L10: Active
A11: 8 | B11: jmWILLIAMS, CPA LLP | C11: Ammie, Jyoti | D11: B.Tax, I.Tax | E11: 1200 | F11: =IF(E11="",0,E11*Settings!B8) -> 102000 | I11: CAS 139 | J11: 160 | K11: 41 | L11: In Progress
A12: 9 | B12: MARTIN EINSTEIN | C12: Ammie, Jyoti, Nikita | D12: Acctg, B.Tax, I.Tax, VA | E12: 1440 | F12: =IF(E12="",0,E12*Settings!B8) -> 122400 | I12: CAS 144 | J12: 400 | K12: 38 | L12: In Progress
A13: 10 | B13: DOR BUSINESS GROUP LLC | C13: Ayushi | D13: Accounting | E13: 350 | F13: =IF(E13="",0,E13*Settings!B8) -> 29750 | I13: CAS 149 | J13: 40 | K13: 7 | L13: In Progress
A14: 11 | B14: CHRIS WHALEN CPA, LLC | C14: Ammie, Nikita | D14: Acctg, I.Tax | E14: 1880 | F14: =IF(E14="",0,E14*Settings!B8) -> 159800 | I14: CAS 153 | J14: 320 | K14: 64 | L14: Active
A15: 12 | B15: TREE OF LIFE FUNDING | C15: Nikita | D15: Accounting | E15: 1200 | F15: =IF(E15="",0,E15*Settings!B8) -> 102000 | I15: CAS 161 | J15: 160 | L15: In Progress
A16: 13 | B16: ROSEN KUSLANSKY CPA PC | C16: Nikita | D16: Accounting | E16: 1000 | F16: =IF(E16="",0,E16*Settings!B8) -> 85000 | I16: CAS 162 | J16: 160 | K16: 31 | L16: Active
A17: 14 | B17: INVENT WEALTH, CPA | C17: Ammie, Jasleen.D, Jyoti | D17: Acctg, B.Tax, I.Tax | E17: 2640 | F17: =IF(E17="",0,E17*Settings!B8) -> 224400 | I17: CAS 114 | J17: 480 | K17: 72 | L17: In Progress
A18: 15 | B18: ACT NOW FINANCIAL SERVICES | C18: Nikita | D18: Accounting | E18: 800 | F18: =IF(E18="",0,E18*Settings!B8) -> 68000 | I18: CAS 169 | J18: 80 | K18: 16 | L18: In Progress
A19: 16 | B19: BRADLEY FINANCIAL SERVICES LLC | C19: Jasleen.D | D19: Accounting | E19: 700 | F19: =IF(E19="",0,E19*Settings!B8) -> 59500 | I19: CAS 170 | J19: 140 | K19: 11 | L19: Active
A20: 17 | B20: JOHNSON & ROBINSON LLC | C20: Nikita | D20: Accounting | E20: 800 | F20: =IF(E20="",0,E20*Settings!B8) -> 68000 | I20: CAS 172 | J20: 80 | K20: 44 | L20: Active
A21: 18 | B21: PW ADVISORS LLC | C21: Ammie, Jyoti, Nikita | D21: Acctg, B.Tax, I.Tax | E21: 3600 | F21: =IF(E21="",0,E21*Settings!B8) -> 306000 | I21: CAS 175 | J21: 480 | K21: 50 | L21: Active
A22: 19 | B22: LIFETIME FUNDING, LLC | C22: Ayushi | D22: Accounting | E22: 1900 | F22: =IF(E22="",0,E22*Settings!B8) -> 161500 | I22: CAS 178 | J22: 400 | K22: 1 | L22: In Progress
A23: 20 | B23: NEW AGE IRON WORKS, INC. | C23: Ayushi | D23: Accounting | E23: 1000 | F23: =IF(E23="",0,E23*Settings!B8) -> 85000 | I23: CAS 193 | J23: 160 | K23: 1 | L23: In Progress
A24: 21 | B24: MCFADDEN ACCOUNTING | C24: Nikita | D24: Accounting | E24: 1000 | F24: =IF(E24="",0,E24*Settings!B8) -> 85000 | I24: CAS 199 | J24: 160 | K24: 14 | L24: Active
A25: 22 | B25: IAM ACCOUNTING | C25: Jasleen.D | D25: Accounting | E25: 3400 | F25: =IF(E25="",0,E25*Settings!B8) -> 289000 | I25: CAS 202 | J25: 320 | K25: 29 | L25: In Progress
A26: 23 | B26: H J EDWARDS | C26: Nikita | D26: Accounting | E26: 600 | F26: =IF(E26="",0,E26*Settings!B8) -> 51000 | I26: CAS 204 | J26: 80 | K26: 12 | L26: Active
A27: 24 | B27: RTWXXACT | C27: Ayushi | D27: Accounting | E27: 1000 | F27: =IF(E27="",0,E27*Settings!B8) -> 85000 | I27: CAS 208 | J27: 160 | K27: 12 | L27: In Progress
A28: 25 | B28: BORISMTAX INC | C28: Ayushi | D28: Accounting | E28: 3600 | F28: =IF(E28="",0,E28*Settings!B8) -> 306000 | I28: CAS 214 | J28: 480 | K28: 40 | L28: In Progress
A29: 26 | B29: LASTMILE DELIVERY | C29: Nikita | D29: Accounting | E29: 500 | F29: =IF(E29="",0,E29*Settings!B8) -> 42500 | I29: CAS 216 | J29: 160 | K29: 2 | L29: Active
A30: 27 | B30: NEWELL TAYLOR CPA | C30: Jasleen.D | D30: Accounting | E30: 1000 | F30: =IF(E30="",0,E30*Settings!B8) -> 85000 | I30: CAS 219 | J30: 160 | K30: 18 | L30: Active
A31: 28 | B31: WEAREQUADRANT | C31: Ayushi, Nikita | D31: Accounting | E31: 3200 | F31: =IF(E31="",0,E31*Settings!B8) -> 272000 | I31: CAS 220 | J31: 240 | K31: 41 | L31: Active
A32: 29 | B32: BUSINESS NAVIGATORS LLC | C32: Jasleen.D | D32: Accounting | E32: 1000 | F32: =IF(E32="",0,E32*Settings!B8) -> 85000 | I32: CAS 163 | J32: 161 | K32: 9 | L32: In Progress
A33: 30 | B33: RRAW CPA LLP | C33: Jasleen.D | D33: Accounting | E33: 400 | F33: =IF(E33="",0,E33*Settings!B8) -> 34000 | I33: CAS 222 | J33: 40 | K33: 4 | L33: Active
A34: 31 | B34: AMI HOLDING | C34: Sachi, Vinita | D34: FP&A, HR | E34: 21820 | F34: =IF(E34="",0,E34*Settings!B8) -> 1854700 | I34: CAS 223 | J34: 960 | K34: 1 | L34: Finished
A35: 32 | B35: PROVISION ACCOUNTING SOLUTIONS | C35: Ammie, Jyoti | D35: B.Tax, I.Tax | E35: 250 | F35: =IF(E35="",0,E35*Settings!B8) -> 21250 | I35: CAS 226 | J35: 220 | K35: 23 | L35: In Progress
A36: 33 | B36: MERAKI ACCOUNTING & TAX LLC | C36: Ayushi | D36: Accounting | E36: 600 | F36: =IF(E36="",0,E36*Settings!B8) -> 51000 | I36: CAS 229 | J36: 80 | K36: 31 | L36: In Progress
A37: 34 | B37: MAINSPRING SOLUTIONS | C37: Jasleen.D | D37: Accounting | E37: 1200 | F37: =IF(E37="",0,E37*Settings!B8) -> 102000 | I37: CAS 230 | J37: 160 | K37: 14 | L37: Active
A38: 35 | B38: HELLO ACCOUNTAX | C38: Ayushi | D38: Accounting | E38: 600 | F38: =IF(E38="",0,E38*Settings!B8) -> 51000 | I38: CAS 231 | J38: 140 | K38: 7 | L38: In Progress
A39: 36 | B39: XPERT BOOKKEEPING LLC | C39: Nikita | D39: Accounting | E39: 1100 | F39: =IF(E39="",0,E39*Settings!B8) -> 93500 | I39: CAS 234 | J39: 200 | K39: 10 | L39: In Progress
A40: 37 | B40: THINKING MAPS, INC. | C40: Nikita | D40: Accounting | E40: 2600 | F40: =IF(E40="",0,E40*Settings!B8) -> 221000 | I40: CAS 236 | J40: 320 | L40: Active
...

Sheet ④ Client-Service Map
A1: CLIENT-SERVICE MAPPING (Seats Allocation)
A2: Instructions: Enter which services each client uses and how many seats (FTEs allocated).
A3: Client Name | B3: Service | C3: Seats Allocated | D3: Status | E3: Controller
A4: 406 CONSULTING LLC | B4: Business Tax | C4: 0.6 | D4: ACTIVE
A5: 406 CONSULTING LLC | B5: Individual Tax | C5: 1.4 | D5: ACTIVE
A6: 4P TAXES LLC | B6: Accounting | C6: 1 | D6: ACTIVE
A7: AB CAPSTONE GROUP | B7: Accounting | C7: 1.5 | D7: ACTIVE
A8: ABACUS BUSINESS SOLUTIONS, LLC | B8: Accounting | C8: 4 | D8: ACTIVE
A9: ACE CPA | B9: Accounting | C9: 2 | D9: ACTIVE
A10: ACT NOW FINANCIAL SERVICES, LLC | B10: Accounting | C10: 0.5 | D10: ACTIVE
A11: ACTION ACCOUNTING | B11: Accounting | C11: 1 | D11: ACTIVE
A12: ACTION ACCOUNTING | B12: Business Tax | C12: 0.15 | D12: ACTIVE
A13: ACTION ACCOUNTING | B13: Individual Tax | C13: 0.35 | D13: ACTIVE
A14: AMI US HOLDING INC. | B14: FP&A | C14: 5 | D14: ACTIVE
A15: AMI US HOLDING INC. | B15: HR | C15: 1 | D15: ACTIVE
... A90: XPERT BOOKKEEPING LLC | B90: Accounting | C90: 1 | D90: ACTIVE

Sheet ⑤ Emp-Client Hours
A1: EMPLOYEE-CLIENT HOURS MAPPING (AUTO-GENERATED)
A2: Formula-driven from ① Timelog Input. Each row = one employee × one client combination with hours > 0.
A3: Employee Name | B3: Employee ID | C3: Client Name | D3: Hours on Client | E3: Department | F3: Is Overhead? | G3: Emp Hourly Rate (₹) AUTO
A4: ='① Timelog Input'!B4 -> Ankit | B4: ='① Timelog Input'!C4 -> CAS-IH_1070 | C4: ='① Timelog Input'!R$3 -> 4P TAXES LLC | D4: ='① Timelog Input'!R4 -> 21.5 | E4: ='① Timelog Input'!H4 -> Accounting | F4: =IF(OR(E4="HR",E4="IT",E4="Marketing"),"YES","NO") -> NO | G4: =IFERROR(VLOOKUP(B4,'② Salary Input'!A:V,14,FALSE())/Settings!B6,0) -> 375
A5: ='① Timelog Input'!B4 -> Ankit | B5: ='① Timelog Input'!C4 -> CAS-IH_1070 | C5: ='① Timelog Input'!AI$3 -> CLOUDIT | D5: ='① Timelog Input'!AI4 -> 5.84 | E5: ='① Timelog Input'!H4 -> Accounting | F5: =IF(OR(E5="HR",E5="IT",E5="Marketing"),"YES","NO") -> NO | G5: =IFERROR(VLOOKUP(B5,'② Salary Input'!A:V,14,FALSE())/Settings!B6,0) -> 375
A6: ='① Timelog Input'!B4 -> Ankit | B6: ='① Timelog Input'!C4 -> CAS-IH_1070 | C6: ='① Timelog Input'!AR$3 -> IAM ACCOUNTING LLC | D6: ='① Timelog Input'!AR4 -> 86.08 | E6: ='① Timelog Input'!H4 -> Accounting | F6: =IF(OR(E6="HR",E6="IT",E6="Marketing"),"YES","NO") -> NO | G6: =IFERROR(VLOOKUP(B6,'② Salary Input'!A:V,14,FALSE())/Settings!B6,0) -> 375
A7: ='① Timelog Input'!B5 -> Astha.D | B7: ='① Timelog Input'!C5 -> CAS-IH_1092 | C7: ='① Timelog Input'!AT$3 -> INVENT WEALTH, CPA | D7: ='① Timelog Input'!AT5 -> 156.75 | E7: ='① Timelog Input'!H5 -> Accounting | F7: =IF(OR(E7="HR",E7="IT",E7="Marketing"),"YES","NO") -> NO | G7: =IFERROR(VLOOKUP(B7,'② Salary Input'!A:V,14,FALSE())/Settings!B6,0) -> 281.25
A8: ='① Timelog Input'!B6 -> Pragati.S | B8: ='① Timelog Input'!C6 -> CAS-IH_1105 | C8: ='① Timelog Input'!AC$3 -> BRIGHTSKIES BUSINESS SERVICES, LLC | D8: ='① Timelog Input'!AC6 -> 69.58 | E8: ='① Timelog Input'!H6 -> Accounting | F8: =IF(OR(E8="HR",E8="IT",E8="Marketing"),"YES","NO") -> NO | G8: =IFERROR(VLOOKUP(B8,'② Salary Input'!A:V,14,FALSE())/Settings!B6,0) -> 406.25
A9: ='① Timelog Input'!B6 -> Pragati.S | B9: ='① Timelog Input'!C6 -> CAS-IH_1105 | C9: ='① Timelog Input'!AI$3 -> CLOUDIT | D9: ='① Timelog Input'!AI6 -> 16.61 | E9: ='① Timelog Input'!H6 -> Accounting | F9: =IF(OR(E9="HR",E9="IT",E9="Marketing"),"YES","NO") -> NO | G9: =IFERROR(VLOOKUP(B9,'② Salary Input'!A:V,14,FALSE())/Settings!B6,0) -> 406.25
A10: ='① Timelog Input'!B6 -> Pragati.S | B10: ='① Timelog Input'!C6 -> CAS-IH_1105 | C10: ='① Timelog Input'!AT$3 -> INVENT WEALTH, CPA | D10: ='① Timelog Input'!AT6 -> 3.82 | E10: ='① Timelog Input'!H6 -> Accounting | F10: =IF(OR(E10="HR",E10="IT",E10="Marketing"),"YES","NO") -> NO | G10: =IFERROR(VLOOKUP(B10,'② Salary Input'!A:V,14,FALSE())/Settings!B6,0) -> 406.25
A11: ='① Timelog Input'!B6 -> Pragati.S | B11: ='① Timelog Input'!C6 -> CAS-IH_1105 | C11: ='① Timelog Input'!AY$3 -> MAINSPRING SOLUTIONS | D11: ='① Timelog Input'!AY6 -> 27.4 | E11: ='① Timelog Input'!H6 -> Accounting | F11: =IF(OR(E11="HR",E11="IT",E11="Marketing"),"YES","NO") -> NO | G11: =IFERROR(VLOOKUP(B11,'② Salary Input'!A:V,14,FALSE())/Settings!B6,0) -> 406.25
A12: ='① Timelog Input'!B6 -> Pragati.S | B12: ='① Timelog Input'!C6 -> CAS-IH_1105 | C12: ='① Timelog Input'!BA$3 -> MATHESON & ASSOCIATES | D12: ='① Timelog Input'!BA6 -> 8.17 | E12: ='① Timelog Input'!H6 -> Accounting | F12: =IF(OR(E12="HR",E12="IT",E12="Marketing"),"YES","NO") -> NO | G12: =IFERROR(VLOOKUP(B12,'② Salary Input'!A:V,14,FALSE())/Settings!B6,0) -> 406.25
A13: ='① Timelog Input'!B7 -> Anshul.O | B13: ='① Timelog Input'!C7 -> CAS-IH_1109 | C13: ='① Timelog Input'!Y$3 -> ANCIENT CITY ACCOUNTING LLC | D13: ='① Timelog Input'!Y7 -> 4.5 | E13: ='① Timelog Input'!H7 -> Accounting | F13: =IF(OR(E13="HR",E13="IT",E13="Marketing"),"YES","NO") -> NO | G13: =IFERROR(VLOOKUP(B13,'② Salary Input'!A:V,14,FALSE())/Settings!B6,0) -> 525
A14: ='① Timelog Input'!B7 -> Anshul.O | B14: ='① Timelog Input'!C7 -> CAS-IH_1109 | C14: ='① Timelog Input'!AC$3 -> BRIGHTSKIES BUSINESS SERVICES, LLC | D14: ='① Timelog Input'!AC7 -> 31.67 | E14: ='① Timelog Input'!H7 -> Accounting | F14: =IF(OR(E14="HR",E14="IT",E14="Marketing"),"YES","NO") -> NO | G14: =IFERROR(VLOOKUP(B14,'② Salary Input'!A:V,14,FALSE())/Settings!B6,0) -> 525
A15: ='① Timelog Input'!B7 -> Anshul.O | B15: ='① Timelog Input'!C7 -> CAS-IH_1109 | C15: ='① Timelog Input'!AD$3 -> BUSINESS NAVIGATORS LLC | D15: ='① Timelog Input'!AD7 -> 9.5 | E15: ='① Timelog Input'!H7 -> Accounting | F15: =IF(OR(E15="HR",E15="IT",E15="Marketing"),"YES","NO") -> NO | G15: =IFERROR(VLOOKUP(B15,'② Salary Input'!A:V,14,FALSE())/Settings!B6,0) -> 525
A16: ='① Timelog Input'!B7 -> Anshul.O | B16: ='① Timelog Input'!C7 -> CAS-IH_1109 | C16: ='① Timelog Input'!AI$3 -> CLOUDIT | D16: ='① Timelog Input'!AI7 -> 19.5 | E16: ='① Timelog Input'!H7 -> Accounting | F16: =IF(OR(E16="HR",E16="IT",E16="Marketing"),"YES","NO") -> NO | G16: =IFERROR(VLOOKUP(B16,'② Salary Input'!A:V,14,FALSE())/Settings!B6,0) -> 525
A17: ='① Timelog Input'!B7 -> Anshul.O | B17: ='① Timelog Input'!C7 -> CAS-IH_1109 | C17: ='① Timelog Input'!AQ$3 -> HIA TAX | D17: ='① Timelog Input'!AQ7 -> 6 | E17: ='① Timelog Input'!H7 -> Accounting | F17: =IF(OR(E17="HR",E17="IT",E17="Marketing"),"YES","NO") -> NO | G17: =IFERROR(VLOOKUP(B17,'② Salary Input'!A:V,14,FALSE())/Settings!B6,0) -> 525
A18: ='① Timelog Input'!B7 -> Anshul.O | B18: ='① Timelog Input'!C7 -> CAS-IH_1109 | C18: ='① Timelog Input'!AT$3 -> INVENT WEALTH, CPA | D18: ='① Timelog Input'!AT7 -> 19.5 | E18: ='① Timelog Input'!H7 -> Accounting | F18: =IF(OR(E18="HR",E18="IT",E18="Marketing"),"YES","NO") -> NO | G18: =IFERROR(VLOOKUP(B18,'② Salary Input'!A:V,14,FALSE())/Settings!B6,0) -> 525
A19: ='① Timelog Input'!B7 -> Anshul.O | B19: ='① Timelog Input'!C7 -> CAS-IH_1109 | C19: ='① Timelog Input'!AY$3 -> MAINSPRING SOLUTIONS | D19: ='① Timelog Input'!AY7 -> 6 | E19: ='① Timelog Input'!H7 -> Accounting | F19: =IF(OR(E19="HR",E19="IT",E19="Marketing"),"YES","NO") -> NO | G19: =IFERROR(VLOOKUP(B19,'② Salary Input'!A:V,14,FALSE())/Settings!B6,0) -> 525
A20: ='① Timelog Input'!B7 -> Anshul.O | B20: ='① Timelog Input'!C7 -> CAS-IH_1109 | C20: ='① Timelog Input'!BA$3 -> MATHESON & ASSOCIATES | D20: ='① Timelog Input'!BA7 -> 0.5 | E20: ='① Timelog Input'!H7 -> Accounting | F20: =IF(OR(E20="HR",E20="IT",E20="Marketing"),"YES","NO") -> NO | G20: =IFERROR(VLOOKUP(B20,'② Salary Input'!A:V,14,FALSE())/Settings!B6,0) -> 525
A21: ='① Timelog Input'!B7 -> Anshul.O | B21: ='① Timelog Input'!C7 -> CAS-IH_1109 | C21: ='① Timelog Input'!BG$3 -> NEWELL TAYLOR CPA | D21: ='① Timelog Input'!BG7 -> 2 | E21: ='① Timelog Input'!H7 -> Accounting | F21: =IF(OR(E21="HR",E21="IT",E21="Marketing"),"YES","NO") -> NO | G21: =IFERROR(VLOOKUP(B21,'② Salary Input'!A:V,14,FALSE())/Settings!B6,0) -> 525
A22: ='① Timelog Input'!B7 -> Anshul.O | B22: ='① Timelog Input'!C7 -> CAS-IH_1109 | C22: ='① Timelog Input'!BO$3 -> RRAW CPA LLP | D22: ='① Timelog Input'!BO7 -> 5 | E22: ='① Timelog Input'!H7 -> Accounting | F22: =IF(OR(E22="HR",E22="IT",E22="Marketing"),"YES","NO") -> NO | G22: =IFERROR(VLOOKUP(B22,'② Salary Input'!A:V,14,FALSE())/Settings!B6,0) -> 525
A23: ='① Timelog Input'!B7 -> Anshul.O | B23: ='① Timelog Input'!C7 -> CAS-IH_1109 | C23: ='① Timelog Input'!BZ$3 -> WB MORROW | D23: ='① Timelog Input'!BZ7 -> 53.25 | E23: ='① Timelog Input'!H7 -> Accounting | F23: =IF(OR(E23="HR",E23="IT",E23="Marketing"),"YES","NO") -> NO | G23: =IFERROR(VLOOKUP(B23,'② Salary Input'!A:V,14,FALSE())/Settings!B6,0) -> 525
A24: ='① Timelog Input'!B8 -> Shefali.B | B24: ='① Timelog Input'!C8 -> CAS-IH_1122 | C24: ='① Timelog Input'!AI$3 -> CLOUDIT | D24: ='① Timelog Input'!AI8 -> 5.92 | E24: ='① Timelog Input'!H8 -> Accounting | F24: =IF(OR(E24="HR",E24="IT",E24="Marketing"),"YES","NO") -> NO | G24: =IFERROR(VLOOKUP(B24,'② Salary Input'!A:V,14,FALSE())/Settings!B6,0) -> 281.25
A25: ='① Timelog Input'!B8 -> Shefali.B | B25: ='① Timelog Input'!C8 -> CAS-IH_1122 | C25: ='① Timelog Input'!BA$3 -> MATHESON & ASSOCIATES | D25: ='① Timelog Input'!BA8 -> 141.49 | E25: ='① Timelog Input'!H8 -> Accounting | F25: =IF(OR(E25="HR",E25="IT",E25="Marketing"),"YES","NO") -> NO | G25: =IFERROR(VLOOKUP(B25,'② Salary Input'!A:V,14,FALSE())/Settings!B6,0) -> 281.25
A26: ='① Timelog Input'!B9 -> Sandesh.H | B26: ='① Timelog Input'!C9 -> CAS-IH_1149 | C26: ='① Timelog Input'!AB$3 -> BRADLEY FINANCIAL SERVICES LLC | D26: ='① Timelog Input'!AB9 -> 43.5 | E26: ='① Timelog Input'!H9 -> Accounting | F26: =IF(OR(E26="HR",E26="IT",E26="Marketing"),"YES","NO") -> NO | G26: =IFERROR(VLOOKUP(B26,'② Salary Input'!A:V,14,FALSE())/Settings!B6,0) -> 250
A27: ='① Timelog Input'!B9 -> Sandesh.H | B27: ='① Timelog Input'!C9 -> CAS-IH_1149 | C27: ='① Timelog Input'!AC$3 -> BRIGHTSKIES BUSINESS SERVICES, LLC | D27: ='① Timelog Input'!AC9 -> 122.5 | E27: ='① Timelog Input'!H9 -> Accounting | F27: =IF(OR(E27="HR",E27="IT",E27="Marketing"),"YES","NO") -> NO | G27: =IFERROR(VLOOKUP(B27,'② Salary Input'!A:V,14,FALSE())/Settings!B6,0) -> 250
A28: ='① Timelog Input'!B10 -> Robin.S | B28: ='① Timelog Input'!C10 -> CAS-IH_1162 | C28: ='① Timelog Input'!AI$3 -> CLOUDIT | D28: ='① Timelog Input'!AI10 -> 1 | E28: ='① Timelog Input'!H10 -> Accounting | F28: =IF(OR(E28="HR",E28="IT",E28="Marketing"),"YES","NO") -> NO | G28: =IFERROR(VLOOKUP(B28,'② Salary Input'!A:V,14,FALSE())/Settings!B6,0) -> 250
A29: ='① Timelog Input'!B10 -> Robin.S | B29: ='① Timelog Input'!C10 -> CAS-IH_1162 | C29: ='① Timelog Input'!AT$3 -> INVENT WEALTH, CPA | D29: ='① Timelog Input'!AT10 -> 140.24 | E29: ='① Timelog Input'!H10 -> Accounting | F29: =IF(OR(E29="HR",E29="IT",E29="Marketing"),"YES","NO") -> NO | G29: =IFERROR(VLOOKUP(B29,'② Salary Input'!A:V,14,FALSE())/Settings!B6,0) -> 250
A30: ='① Timelog Input'!B11 -> Vijet.B | B30: ='① Timelog Input'!C11 -> CAS-RR_2371 | C30: ='① Timelog Input'!AI$3 -> CLOUDIT | D30: ='① Timelog Input'!AI11 -> 2 | E30: ='① Timelog Input'!H11 -> Accounting | F30: =IF(OR(E30="HR",E30="IT",E30="Marketing"),"YES","NO") -> NO | G30: =IFERROR(VLOOKUP(B30,'② Salary Input'!A:V,14,FALSE())/Settings!B6,0) -> 200
A31: ='① Timelog Input'!B11 -> Vijet.B | B31: ='① Timelog Input'!C11 -> CAS-RR_2371 | C31: ='① Timelog Input'!AQ$3 -> HIA TAX | D31: ='① Timelog Input'!AQ11 -> 73 | E31: ='① Timelog Input'!H11 -> Accounting | F31: =IF(OR(E31="HR",E31="IT",E31="Marketing"),"YES","NO") -> NO | G31: =IFERROR(VLOOKUP(B31,'② Salary Input'!A:V,14,FALSE())/Settings!B6,0) -> 200
A32: ='① Timelog Input'!B11 -> Vijet.B | B32: ='① Timelog Input'!C11 -> CAS-RR_2371 | C32: ='① Timelog Input'!BG$3 -> NEWELL TAYLOR CPA | D32: ='① Timelog Input'!BG11 -> 82.75 | E32: ='① Timelog Input'!H11 -> Accounting | F32: =IF(OR(E32="HR",E32="IT",E32="Marketing"),"YES","NO") -> NO | G32: =IFERROR(VLOOKUP(B32,'② Salary Input'!A:V,14,FALSE())/Settings!B6,0) -> 200
A33: ='① Timelog Input'!B12 -> Somya.B | B33: ='① Timelog Input'!C12 -> CAS-IH_1169 | C33: ='① Timelog Input'!Y$3 -> ANCIENT CITY ACCOUNTING LLC | D33: ='① Timelog Input'!Y12 -> 139.75 | E33: ='① Timelog Input'!H12 -> Accounting | F33: =IF(OR(E33="HR",E33="IT",E33="Marketing"),"YES","NO") -> NO | G33: =IFERROR(VLOOKUP(B33,'② Salary Input'!A:V,14,FALSE())/Settings!B6,0) -> 312.5
A34: ='① Timelog Input'!B12 -> Somya.B | B34: ='① Timelog Input'!C12 -> CAS-IH_1169 | C34: ='① Timelog Input'!AI$3 -> CLOUDIT | D34: ='① Timelog Input'!AI12 -> 7 | E34: ='① Timelog Input'!H12 -> Accounting | F34: =IF(OR(E34="HR",E34="IT",E34="Marketing"),"YES","NO") -> NO | G34: =IFERROR(VLOOKUP(B34,'② Salary Input'!A:V,14,FALSE())/Settings!B6,0) -> 312.5
A35: ='① Timelog Input'!B13 -> Jasleen.D | B35: ='① Timelog Input'!C13 -> CAS-IH_1069 | C35: ='① Timelog Input'!Q$3 -> 406 CONSULTING LLC | D35: ='① Timelog Input'!Q13 -> 0 | E35: ='① Timelog Input'!H13 -> Accounting | F35: =IF(OR(E35="HR",E35="IT",E35="Marketing"),"YES","NO") -> NO | G35: =IFERROR(VLOOKUP(B35,'② Salary Input'!A:V,14,FALSE())/Settings!B6,0) -> 1531.25
A36: ='① Timelog Input'!B13 -> Jasleen.D | B36: ='① Timelog Input'!C13 -> CAS-IH_1069 | C36: ='① Timelog Input'!AI$3 -> CLOUDIT | D36: ='① Timelog Input'!AI13 -> 54 | E36: ='① Timelog Input'!H13 -> Accounting | F36: =IF(OR(E36="HR",E36="IT",E36="Marketing"),"YES","NO") -> NO | G36: =IFERROR(VLOOKUP(B36,'② Salary Input'!A:V,14,FALSE())/Settings!B6,0) -> 1531.25
A37: ='① Timelog Input'!B13 -> Jasleen.D | B37: ='① Timelog Input'!C13 -> CAS-IH_1069 | C37: ='① Timelog Input'!AM$3 -> Fleming Accounting Solutions | D37: ='① Timelog Input'!AM13 -> 0 | E37: ='① Timelog Input'!H13 -> Accounting | F37: =IF(OR(E37="HR",E37="IT",E37="Marketing"),"YES","NO") -> NO | G37: =IFERROR(VLOOKUP(B37,'② Salary Input'!A:V,14,FALSE())/Settings!B6,0) -> 1531.25
A38: ='① Timelog Input'!B13 -> Jasleen.D | B38: ='① Timelog Input'!C13 -> CAS-IH_1069 | C38: ='① Timelog Input'!AN$3 -> FULL COMPLIANCE, LLC | D38: ='① Timelog Input'!AN13 -> 0 | E38: ='① Timelog Input'!H13 -> Accounting | F38: =IF(OR(E38="HR",E38="IT",E38="Marketing"),"YES","NO") -> NO | G38: =IFERROR(VLOOKUP(B38,'② Salary Input'!A:V,14,FALSE())/Settings!B6,0) -> 1531.25
A39: ='① Timelog Input'!B13 -> Jasleen.D | B39: ='① Timelog Input'!C13 -> CAS-IH_1069 | C39: ='① Timelog Input'!AT$3 -> INVENT WEALTH, CPA | D39: ='① Timelog Input'!AT13 -> 2 | E39: ='① Timelog Input'!H13 -> Accounting | F39: =IF(OR(E39="HR",E39="IT",E39="Marketing"),"YES","NO") -> NO | G39: =IFERROR(VLOOKUP(B39,'② Salary Input'!A:V,14,FALSE())/Settings!B6,0) -> 1531.25
A40: ='① Timelog Input'!B13 -> Jasleen.D | B40: ='① Timelog Input'!C13 -> CAS-IH_1069 | C40: ='① Timelog Input'!AZ$3 -> MARTIN D. EISENSTEIN, CPA | D40: ='① Timelog Input'!AZ13 -> 0 | E40: ='① Timelog Input'!H13 -> Accounting | F40: =IF(OR(E40="HR",E40="IT",E40="Marketing"),"YES","NO") -> NO | G40: =IFERROR(VLOOKUP(B40,'② Salary Input'!A:V,14,FALSE())/Settings!B6,0) -> 1531.25
...

Sheet ⑥ Annual Performance
A1: ANNUAL PERFORMANCE SUMMARY — Last 12 Months (INPUT)
A2: Paste your 12-month aggregated data per employee here. GREEN cells = your input. GRAY cells = auto-calculated from your data.
A3: Employee ID | B3: Employee Name | C3: Emp Type | D3: Designation | E3: Department | F3: Controller | G3: Total Hours (12 Months) | H3: Billable Hours (12 Months) | I3: Non-Billable Hours | J3: Avg Monthly Utilization % | K3: # Clients Served | L3: Avg Client Satisfaction (1-5) | M3: Revenue Generated (₹ 12-Month) | N3: Revenue/Hour (₹) AUTO | O3: # Tasks Completed | P3: # Errors/ Rework | Q3: Accuracy % AUTO | R3: Tenure (Months)
A4: =IF('Employee Master'!B4="","",'Employee Master'!B4) -> CAS-IH_1070 | B4: =IF('Employee Master'!B4="","",'Employee Master'!C4) -> Ankit | C4: =IF('Employee Master'!B4="","",'Employee Master'!D4) -> In-house | D4: =IF('Employee Master'!B4="","",'Employee Master'!E4) -> Associate | E4: =IF('Employee Master'!B4="","",'Employee Master'!F4) -> Accounting | F4: =IF('Employee Master'!B4="","",'Employee Master'!G4) -> Jasleen.D | G4: 127.2 | H4: 127.2 | I4: =IF(A4="","",G4-H4) -> 0 | J4: =IF(A4="","",IF(H4=0,0,H4/(Settings!B6*12))) -> 0.06625 | K4: 3 | L4: 3.5 | M4: 0 | N4: =IF(A4="","",IF(H4=0,0,M4/H4)) -> 0 | O4: 0 | P4: 0 | Q4: =IF(A4="","",IF(O4=0,0,1-P4/O4)) -> 0 | R4: 12
A5: =IF('Employee Master'!B5="","",'Employee Master'!B5) -> CAS-IH_1092 | B5: =IF('Employee Master'!B5="","",'Employee Master'!C5) -> Astha.D | C5: =IF('Employee Master'!B5="","",'Employee Master'!D5) -> In-house | D5: =IF('Employee Master'!B5="","",'Employee Master'!E5) -> Associate | E5: =IF('Employee Master'!B5="","",'Employee Master'!F5) -> Accounting | F5: =IF('Employee Master'!B5="","",'Employee Master'!G5) -> Jasleen.D | G5: 149.8 | H5: 149.8 | I5: =IF(A5="","",G5-H5) -> 0 | J5: =IF(A5="","",IF(H5=0,0,H5/(Settings!B6*12))) -> 0.078020833 | K5: 1 | L5: 3.5 | M5: 0 | N5: =IF(A5="","",IF(H5=0,0,M5/H5)) -> 0 | O5: 0 | P5: 0 | Q5: =IF(A5="","",IF(O5=0,0,1-P5/O5)) -> 0 | R5: 12
A6: =IF('Employee Master'!B6="","",'Employee Master'!B6) -> CAS-IH_1105 | B6: =IF('Employee Master'!B6="","",'Employee Master'!C6) -> Pragati.S | C6: =IF('Employee Master'!B6="","",'Employee Master'!D6) -> In-house | D6: =IF('Employee Master'!B6="","",'Employee Master'!E6) -> Asst. Team Lead | E6: =IF('Employee Master'!B6="","",'Employee Master'!F6) -> Accounting | F6: =IF('Employee Master'!B6="","",'Employee Master'!G6) -> Jasleen.D | G6: 161 | H6: 161 | I6: =IF(A6="","",G6-H6) -> 0 | J6: =IF(A6="","",IF(H6=0,0,H6/(Settings!B6*12))) -> 0.083854167 | K6: 6 | L6: 3.5 | M6: 0 | N6: =IF(A6="","",IF(H6=0,0,M6/H6)) -> 0 | O6: 0 | P6: 0 | Q6: =IF(A6="","",IF(O6=0,0,1-P6/O6)) -> 0 | R6: 12
A7: =IF('Employee Master'!B7="","",'Employee Master'!B7) -> CAS-IH_1109 | B7: =IF('Employee Master'!B7="","",'Employee Master'!C7) -> Anshul.O | C7: =IF('Employee Master'!B7="","",'Employee Master'!D7) -> In-house | D7: =IF('Employee Master'!B7="","",'Employee Master'!E7) -> Team Lead | E7: =IF('Employee Master'!B7="","",'Employee Master'!F7) -> Accounting | F7: =IF('Employee Master'!B7="","",'Employee Master'!G7) -> Jasleen.D | G7: 152.6 | H7: 152.6 | I7: =IF(A7="","",G7-H7) -> 0 | J7: =IF(A7="","",IF(H7=0,0,H7/(Settings!B6*12))) -> 0.079479167 | K7: 10 | L7: 3.5 | M7: 0 | N7: =IF(A7="","",IF(H7=0,0,M7/H7)) -> 0 | O7: 0 | P7: 0 | Q7: =IF(A7="","",IF(O7=0,0,1-P7/O7)) -> 0 | R7: 12
A8: =IF('Employee Master'!B8="","",'Employee Master'!B8) -> CAS-IH_1122 | B8: =IF('Employee Master'!B8="","",'Employee Master'!C8) -> Shefali.B | C8: =IF('Employee Master'!B8="","",'Employee Master'!D8) -> In-house | D8: =IF('Employee Master'!B8="","",'Employee Master'!E8) -> Associate | E8: =IF('Employee Master'!B8="","",'Employee Master'!F8) -> Accounting | F8: =IF('Employee Master'!B8="","",'Employee Master'!G8) -> Jasleen.D | G8: 158.1 | H8: 158.1 | I8: =IF(A8="","",G8-H8) -> 0 | J8: =IF(A8="","",IF(H8=0,0,H8/(Settings!B6*12))) -> 0.08234375 | K8: 2 | L8: 3.5 | M8: 0 | N8: =IF(A8="","",IF(H8=0,0,M8/H8)) -> 0 | O8: 0 | P8: 0 | Q8: =IF(A8="","",IF(O8=0,0,1-P8/O8)) -> 0 | R8: 12
A9: =IF('Employee Master'!B9="","",'Employee Master'!B9) -> CAS-IH_1149 | B9: =IF('Employee Master'!B9="","",'Employee Master'!C9) -> Sandesh.H | C9: =IF('Employee Master'!B9="","",'Employee Master'!D9) -> In-house | D9: =IF('Employee Master'!B9="","",'Employee Master'!E9) -> Associate | E9: =IF('Employee Master'!B9="","",'Employee Master'!F9) -> Accounting | F9: =IF('Employee Master'!B9="","",'Employee Master'!G9) -> Jasleen.D | G9: 176.1 | H9: 176.1 | I9: =IF(A9="","",G9-H9) -> 0 | J9: =IF(A9="","",IF(H9=0,0,H9/(Settings!B6*12))) -> 0.09171875 | K9: 2 | L9: 3.5 | M9: 0 | N9: =IF(A9="","",IF(H9=0,0,M9/H9)) -> 0 | O9: 0 | P9: 0 | Q9: =IF(A9="","",IF(O9=0,0,1-P9/O9)) -> 0 | R9: 12
A10: =IF('Employee Master'!B10="","",'Employee Master'!B10) -> CAS-IH_1162 | B10: =IF('Employee Master'!B10="","",'Employee Master'!C10) -> Robin.S | C10: =IF('Employee Master'!B10="","",'Employee Master'!D10) -> Remote | D10: =IF('Employee Master'!B10="","",'Employee Master'!E10) -> Associate | E10: =IF('Employee Master'!B10="","",'Employee Master'!F10) -> Accounting | F10: =IF('Employee Master'!B10="","",'Employee Master'!G10) -> Jasleen.D | G10: 121.5 | H10: 121.5 | I10: =IF(A10="","",G10-H10) -> 0 | J10: =IF(A10="","",IF(H10=0,0,H10/(Settings!B6*12))) -> 0.06328125 | K10: 2 | L10: 3.5 | M10: 0 | N10: =IF(A10="","",IF(H10=0,0,M10/H10)) -> 0 | O10: 0 | P10: 0 | Q10: =IF(A10="","",IF(O10=0,0,1-P10/O10)) -> 0 | R10: 12
A11: =IF('Employee Master'!B11="","",'Employee Master'!B11) -> CAS-RR_2371 | B11: =IF('Employee Master'!B11="","",'Employee Master'!C11) -> Vijet.B | C11: =IF('Employee Master'!B11="","",'Employee Master'!D11) -> Remote | D11: =IF('Employee Master'!B11="","",'Employee Master'!E11) -> Associate | E11: =IF('Employee Master'!B11="","",'Employee Master'!F11) -> Accounting | F11: =IF('Employee Master'!B11="","",'Employee Master'!G11) -> Jasleen.D | G11: 151 | H11: 151 | I11: =IF(A11="","",G11-H11) -> 0 | J11: =IF(A11="","",IF(H11=0,0,H11/(Settings!B6*12))) -> 0.078645833 | K11: 3 | L11: 3.5 | M11: 0 | N11: =IF(A11="","",IF(H11=0,0,M11/H11)) -> 0 | O11: 0 | P11: 0 | Q11: =IF(A11="","",IF(O11=0,0,1-P11/O11)) -> 0 | R11: 12
A12: =IF('Employee Master'!B12="","",'Employee Master'!B12) -> CAS-IH_1169 | B12: =IF('Employee Master'!B12="","",'Employee Master'!C12) -> Somya.B | C12: =IF('Employee Master'!B12="","",'Employee Master'!D12) -> Retainer | D12: =IF('Employee Master'!B12="","",'Employee Master'!E12) -> Sr. Associate | E12: =IF('Employee Master'!B12="","",'Employee Master'!F12) -> Accounting | F12: =IF('Employee Master'!B12="","",'Employee Master'!G12) -> Jasleen.D | G12: 160 | H12: 160 | I12: =IF(A12="","",G12-H12) -> 0 | J12: =IF(A12="","",IF(H12=0,0,H12/(Settings!B6*12))) -> 0.083333333 | K12: 2 | L12: 3.5 | M12: 0 | N12: =IF(A12="","",IF(H12=0,0,M12/H12)) -> 0 | O12: 0 | P12: 0 | Q12: =IF(A12="","",IF(O12=0,0,1-P12/O12)) -> 0 | R12: 12
A13: =IF('Employee Master'!B13="","",'Employee Master'!B13) -> CAS-IH_1069 | B13: =IF('Employee Master'!B13="","",'Employee Master'!C13) -> Jasleen.D | C13: =IF('Employee Master'!B13="","",'Employee Master'!D13) -> In-house | D13: =IF('Employee Master'!B13="","",'Employee Master'!E13) -> Controller | E13: =IF('Employee Master'!B13="","",'Employee Master'!F13) -> Accounting | F13: =IF('Employee Master'!B13="","",'Employee Master'!G13) -> -- | G13: 140 | H13: 140 | I13: =IF(A13="","",G13-H13) -> 0 | J13: =IF(A13="","",IF(H13=0,0,H13/(Settings!B6*12))) -> 0.072916667 | K13: 16 | L13: 3.5 | M13: 0 | N13: =IF(A13="","",IF(H13=0,0,M13/H13)) -> 0 | O13: 0 | P13: 0 | Q13: =IF(A13="","",IF(O13=0,0,1-P13/O13)) -> 0 | R13: 12
A14: =IF('Employee Master'!B14="","",'Employee Master'!B14) -> CAS-IH_1037 | B14: =IF('Employee Master'!B14="","",'Employee Master'!C14) -> Jyoti | C14: =IF('Employee Master'!B14="","",'Employee Master'!D14) -> In-house | D14: =IF('Employee Master'!B14="","",'Employee Master'!E14) -> Controller | E14: =IF('Employee Master'!B14="","",'Employee Master'!F14) -> Accounting, Business Tax, VA | F14: =IF('Employee Master'!B14="","",'Employee Master'!G14) -> -- | G14: 109.2 | H14: 109.2 | I14: =IF(A14="","",G14-H14) -> 0 | J14: =IF(A14="","",IF(H14=0,0,H14/(Settings!B6*12))) -> 0.056875 | K14: 4 | L14: 3.5 | M14: 0 | N14: =IF(A14="","",IF(H14=0,0,M14/H14)) -> 0 | O14: 0 | P14: 0 | Q14: =IF(A14="","",IF(O14=0,0,1-P14/O14)) -> 0 | R14: 12
A15: =IF('Employee Master'!B15="","",'Employee Master'!B15) -> CAS-IH_1018 | B15: =IF('Employee Master'!B15="","",'Employee Master'!C15) -> Vini | C15: =IF('Employee Master'!B15="","",'Employee Master'!D15) -> In-house | D15: =IF('Employee Master'!B15="","",'Employee Master'!E15) -> Controller | E15: =IF('Employee Master'!B15="","",'Employee Master'!F15) -> HR | F15: =IF('Employee Master'!B15="","",'Employee Master'!G15) -> -- | G15: 45 | H15: 45 | I15: =IF(A15="","",G15-H15) -> 0 | J15: =IF(A15="","",IF(H15=0,0,H15/(Settings!B6*12))) -> 0.0234375 | K15: 1 | L15: 3.5 | M15: 0 | N15: =IF(A15="","",IF(H15=0,0,M15/H15)) -> 0 | O15: 0 | P15: 0 | Q15: =IF(A15="","",IF(O15=0,0,1-P15/O15)) -> 0 | R15: 12
A16: =IF('Employee Master'!B16="","",'Employee Master'!B16) -> CAS-IH_1049 | B16: =IF('Employee Master'!B16="","",'Employee Master'!C16) -> Asmita | C16: =IF('Employee Master'!B16="","",'Employee Master'!D16) -> In-house | D16: =IF('Employee Master'!B16="","",'Employee Master'!E16) -> Sr. Associate | E16: =IF('Employee Master'!B16="","",'Employee Master'!F16) -> Accounting, Business Tax | F16: =IF('Employee Master'!B16="","",'Employee Master'!G16) -> Jyoti | G16: 91.8 | H16: 91.8 | I16: =IF(A16="","",G16-H16) -> 0 | J16: =IF(A16="","",IF(H16=0,0,H16/(Settings!B6*12))) -> 0.0478125 | K16: 5 | L16: 3.5 | M16: 0 | N16: =IF(A16="","",IF(H16=0,0,M16/H16)) -> 0 | O16: 0 | P16: 0 | Q16: =IF(A16="","",IF(O16=0,0,1-P16/O16)) -> 0 | R16: 12
A17: =IF('Employee Master'!B17="","",'Employee Master'!B17) -> CAS-IH_1041 | B17: =IF('Employee Master'!B17="","",'Employee Master'!C17) -> Nikita | C17: =IF('Employee Master'!B17="","",'Employee Master'!D17) -> In-house | D17: =IF('Employee Master'!B17="","",'Employee Master'!E17) -> Controller | E17: =IF('Employee Master'!B17="","",'Employee Master'!F17) -> Accounting, Business Tax, VA, L&D | F17: =IF('Employee Master'!B17="","",'Employee Master'!G17) -> -- | G17: 75 | H17: 75 | I17: =IF(A17="","",G17-H17) -> 0 | J17: =IF(A17="","",IF(H17=0,0,H17/(Settings!B6*12))) -> 0.0390625 | K17: 10 | L17: 3.5 | M17: 0 | N17: =IF(A17="","",IF(H17=0,0,M17/H17)) -> 0 | O17: 0 | P17: 0 | Q17: =IF(A17="","",IF(O17=0,0,1-P17/O17)) -> 0 | R17: 12
A18: =IF('Employee Master'!B18="","",'Employee Master'!B18) -> CAS-IH_1051 | B18: =IF('Employee Master'!B18="","",'Employee Master'!C18) -> Ayushi | C18: =IF('Employee Master'!B18="","",'Employee Master'!D18) -> In-house | D18: =IF('Employee Master'!B18="","",'Employee Master'!E18) -> Asst. Controller | E18: =IF('Employee Master'!B18="","",'Employee Master'!F18) -> Accounting, Business Tax | F18: =IF('Employee Master'!B18="","",'Employee Master'!G18) -> -- | G18: 23 | H18: 23 | I18: =IF(A18="","",G18-H18) -> 0 | J18: =IF(A18="","",IF(H18=0,0,H18/(Settings!B6*12))) -> 0.011979167 | K18: 3 | L18: 3.5 | M18: 0 | N18: =IF(A18="","",IF(H18=0,0,M18/H18)) -> 0 | O18: 0 | P18: 0 | Q18: =IF(A18="","",IF(O18=0,0,1-P18/O18)) -> 0 | R18: 12
A19: =IF('Employee Master'!B19="","",'Employee Master'!B19) -> CAS-IH_1065 | B19: =IF('Employee Master'!B19="","",'Employee Master'!C19) -> Shefali | C19: =IF('Employee Master'!B19="","",'Employee Master'!D19) -> In-house | D19: =IF('Employee Master'!B19="","",'Employee Master'!E19) -> Team Lead | E19: =IF('Employee Master'!B19="","",'Employee Master'!F19) -> Accounting | F19: =IF('Employee Master'!B19="","",'Employee Master'!G19) -> Nikita Shah | G19: 105.5 | H19: 105.5 | I19: =IF(A19="","",G19-H19) -> 0 | J19: =IF(A19="","",IF(H19=0,0,H19/(Settings!B6*12))) -> 0.054947917 | K19: 8 | L19: 3.5 | M19: 0 | N19: =IF(A19="","",IF(H19=0,0,M19/H19)) -> 0 | O19: 0 | P19: 0 | Q19: =IF(A19="","",IF(O19=0,0,1-P19/O19)) -> 0 | R19: 12
A20: =IF('Employee Master'!B20="","",'Employee Master'!B20) -> CAS-IH_1077 | B20: =IF('Employee Master'!B20="","",'Employee Master'!C20) -> Rashi | C20: =IF('Employee Master'!B20="","",'Employee Master'!D20) -> In-house | D20: =IF('Employee Master'!B20="","",'Employee Master'!E20) -> Asst. Manager | E20: =IF('Employee Master'!B20="","",'Employee Master'!F20) -> HR | F20: =IF('Employee Master'!B20="","",'Employee Master'!G20) -> Vinita Dagar | G20: 0 | H20: 0 | I20: =IF(A20="","",G20-H20) -> 0 | J20: =IF(A20="","",IF(H20=0,0,H20/(Settings!B6*12))) -> 0 | K20: 0 | L20: 3.5 | M20: 0 | N20: =IF(A20="","",IF(H20=0,0,M20/H20)) -> 0 | O20: 0 | P20: 0 | Q20: =IF(A20="","",IF(O20=0,0,1-P20/O20)) -> 0 | R20: 12
A21: =IF('Employee Master'!B21="","",'Employee Master'!B21) -> CAS-IH_1159 | B21: =IF('Employee Master'!B21="","",'Employee Master'!C21) -> Gaganjot | C21: =IF('Employee Master'!B21="","",'Employee Master'!D21) -> In-house | D21: =IF('Employee Master'!B21="","",'Employee Master'!E21) -> Asst. Team Lead | E21: =IF('Employee Master'!B21="","",'Employee Master'!F21) -> Accounting, Business Tax | F21: =IF('Employee Master'!B21="","",'Employee Master'!G21) -> Nikita Shah | G21: 82.8 | H21: 82.8 | I21: =IF(A21="","",G21-H21) -> 0 | J21: =IF(A21="","",IF(H21=0,0,H21/(Settings!B6*12))) -> 0.043125 | K21: 5 | L21: 3.5 | M21: 0 | N21: =IF(A21="","",IF(H21=0,0,M21/H21)) -> 0 | O21: 0 | P21: 0 | Q21: =IF(A21="","",IF(O21=0,0,1-P21/O21)) -> 0 | R21: 12
A22: =IF('Employee Master'!B22="","",'Employee Master'!B22) -> CAS-IH_1005 | B22: =IF('Employee Master'!B22="","",'Employee Master'!C22) -> Robin | C22: =IF('Employee Master'!B22="","",'Employee Master'!D22) -> In-house | D22: =IF('Employee Master'!B22="","",'Employee Master'!E22) -> Sr. Associate | E22: =IF('Employee Master'!B22="","",'Employee Master'!F22) -> Accounting | F22: =IF('Employee Master'!B22="","",'Employee Master'!G22) -> Jyoti | G22: 158.8 | H22: 158.8 | I22: =IF(A22="","",G22-H22) -> 0 | J22: =IF(A22="","",IF(H22=0,0,H22/(Settings!B6*12))) -> 0.082708333 | K22: 5 | L22: 3.5 | M22: 0 | N22: =IF(A22="","",IF(H22=0,0,M22/H22)) -> 0 | O22: 0 | P22: 0 | Q22: =IF(A22="","",IF(O22=0,0,1-P22/O22)) -> 0 | R22: 12
A23: =IF('Employee Master'!B23="","",'Employee Master'!B23) -> CAS-IH_1038 | B23: =IF('Employee Master'!B23="","",'Employee Master'!C23) -> Nishu | C23: =IF('Employee Master'!B23="","",'Employee Master'!D23) -> In-house | D23: =IF('Employee Master'!B23="","",'Employee Master'!E23) -> Associate | E23: =IF('Employee Master'!B23="","",'Employee Master'!F23) -> Accounting, Business Tax, VA | F23: =IF('Employee Master'!B23="","",'Employee Master'!G23) -> Jyoti | G23: 156.1 | H23: 156.1 | I23: =IF(A23="","",G23-H23) -> 0 | J23: =IF(A23="","",IF(H23=0,0,H23/(Settings!B6*12))) -> 0.081302083 | K23: 1 | L23: 3.5 | M23: 0 | N23: =IF(A23="","",IF(H23=0,0,M23/H23)) -> 0 | O23: 0 | P23: 0 | Q23: =IF(A23="","",IF(O23=0,0,1-P23/O23)) -> 0 | R23: 12
A24: =IF('Employee Master'!B24="","",'Employee Master'!B24) -> CAS-RT_2045 | B24: =IF('Employee Master'!B24="","",'Employee Master'!C24) -> Pinky | C24: =IF('Employee Master'!B24="","",'Employee Master'!D24) -> Remote | D24: =IF('Employee Master'!B24="","",'Employee Master'!E24) -> Manager | E24: =IF('Employee Master'!B24="","",'Employee Master'!F24) -> Accounting | F24: =IF('Employee Master'!B24="","",'Employee Master'!G24) -> Nikita Shah | G24: 96.6 | H24: 96.6 | I24: =IF(A24="","",G24-H24) -> 0 | J24: =IF(A24="","",IF(H24=0,0,H24/(Settings!B6*12))) -> 0.0503125 | K24: 1 | L24: 3.5 | M24: 0 | N24: =IF(A24="","",IF(H24=0,0,M24/H24)) -> 0 | O24: 0 | P24: 0 | Q24: =IF(A24="","",IF(O24=0,0,1-P24/O24)) -> 0 | R24: 12
A25: =IF('Employee Master'!B25="","",'Employee Master'!B25) -> CAS-IH_1056 | B25: =IF('Employee Master'!B25="","",'Employee Master'!C25) -> Preety | C25: =IF('Employee Master'!B25="","",'Employee Master'!D25) -> In-house | D25: =IF('Employee Master'!B25="","",'Employee Master'!E25) -> Team Lead | E25: =IF('Employee Master'!B25="","",'Employee Master'!F25) -> Accounting, Business Tax | F25: =IF('Employee Master'!B25="","",'Employee Master'!G25) -> Nikita Shah | G25: 88.5 | H25: 88.5 | I25: =IF(A25="","",G25-H25) -> 0 | J25: =IF(A25="","",IF(H25=0,0,H25/(Settings!B6*12))) -> 0.04609375 | K25: 8 | L25: 3.5 | M25: 0 | N25: =IF(A25="","",IF(H25=0,0,M25/H25)) -> 0 | O25: 0 | P25: 0 | Q25: =IF(A25="","",IF(O25=0,0,1-P25/O25)) -> 0 | R25: 12
A26: =IF('Employee Master'!B26="","",'Employee Master'!B26) -> CAS-RT_2063 | B26: =IF('Employee Master'!B26="","",'Employee Master'!C26) -> Urvashi | C26: =IF('Employee Master'!B26="","",'Employee Master'!D26) -> Remote | D26: =IF('Employee Master'!B26="","",'Employee Master'!E26) -> Associate | E26: =IF('Employee Master'!B26="","",'Employee Master'!F26) -> Accounting | F26: =IF('Employee Master'!B26="","",'Employee Master'!G26) -> Nikita Shah | G26: 101.5 | H26: 101.5 | I26: =IF(A26="","",G26-H26) -> 0 | J26: =IF(A26="","",IF(H26=0,0,H26/(Settings!B6*12))) -> 0.052864583 | K26: 1 | L26: 3.5 | M26: 0 | N26: =IF(A26="","",IF(H26=0,0,M26/H26)) -> 0 | O26: 0 | P26: 0 | Q26: =IF(A26="","",IF(O26=0,0,1-P26/O26)) -> 0 | R26: 12
A27: =IF('Employee Master'!B27="","",'Employee Master'!B27) -> CAS-IH_1046 | B27: =IF('Employee Master'!B27="","",'Employee Master'!C27) -> Melita | C27: =IF('Employee Master'!B27="","",'Employee Master'!D27) -> In-house | D27: =IF('Employee Master'!B27="","",'Employee Master'!E27) -> Team Lead | E27: =IF('Employee Master'!B27="","",'Employee Master'!F27) -> Individual Tax | F27: =IF('Employee Master'!B27="","",'Employee Master'!G27) -> Smriti Shah | G27: 150.8 | H27: 150.8 | I27: =IF(A27="","",G27-H27) -> 0 | J27: =IF(A27="","",IF(H27=0,0,H27/(Settings!B6*12))) -> 0.078541667 | K27: 7 | L27: 3.5 | M27: 0 | N27: =IF(A27="","",IF(H27=0,0,M27/H27)) -> 0 | O27: 0 | P27: 0 | Q27: =IF(A27="","",IF(O27=0,0,1-P27/O27)) -> 0 | R27: 12
A28: =IF('Employee Master'!B28="","",'Employee Master'!B28) -> CAS-RR_2077 | B28: =IF('Employee Master'!B28="","",'Employee Master'!C28) -> Bhawna | C28: =IF('Employee Master'!B28="","",'Employee Master'!D28) -> Retainer | D28: =IF('Employee Master'!B28="","",'Employee Master'!E28) -> Manager | E28: =IF('Employee Master'!B28="","",'Employee Master'!F28) -> Accounting | F28: =IF('Employee Master'!B28="","",'Employee Master'!G28) -> Jyoti | G28: 162.4 | H28: 162.4 | I28: =IF(A28="","",G28-H28) -> 0 | J28: =IF(A28="","",IF(H28=0,0,H28/(Settings!B6*12))) -> 0.084583333 | K28: 2 | L28: 3.5 | M28: 0 | N28: =IF(A28="","",IF(H28=0,0,M28/H28)) -> 0 | O28: 0 | P28: 0 | Q28: =IF(A28="","",IF(O28=0,0,1-P28/O28)) -> 0 | R28: 12
A29: =IF('Employee Master'!B29="","",'Employee Master'!B29) -> CAS-RT_2078 | B29: =IF('Employee Master'!B29="","",'Employee Master'!C29) -> Anand | C29: =IF('Employee Master'!B29="","",'Employee Master'!D29) -> Remote | D29: =IF('Employee Master'!B29="","",'Employee Master'!E29) -> Associate | E29: =IF('Employee Master'!B29="","",'Employee Master'!F29) -> Accounting | F29: =IF('Employee Master'!B29="","",'Employee Master'!G29) -> Nikita Shah | G29: 155.3 | H29: 155.3 | I29: =IF(A29="","",G29-H29) -> 0 | J29: =IF(A29="","",IF(H29=0,0,H29/(Settings!B6*12))) -> 0.080885417 | K29: 2 | L29: 3.5 | M29: 0 | N29: =IF(A29="","",IF(H29=0,0,M29/H29)) -> 0 | O29: 0 | P29: 0 | Q29: =IF(A29="","",IF(O29=0,0,1-P29/O29)) -> 0 | R29: 12
